I'm sorry, but an uncaught exception occurred.

While running game code:
  File "game/house.rpy", line 10, in script
    e "TEST you are in the second file TEST"
Exception: Sayer 'e' is not defined.

-- Full Traceback ------------------------------------------------------------

Full traceback:
  File "game/house.rpy", line 10, in script
    e "TEST you are in the second file TEST"
  File "C:\Programy\renpy-8.3.2-sdk\renpy\ast.py", line 2573, in execute
    Say.execute(self)
  File "C:\Programy\renpy-8.3.2-sdk\renpy\ast.py", line 575, in execute
    who = eval_who(self.who, self.who_fast)
  File "C:\Programy\renpy-8.3.2-sdk\renpy\ast.py", line 464, in eval_who
    raise Exception("Sayer '%s' is not defined." % who)
Exception: Sayer 'e' is not defined.

Windows-10-10.0.19045 AMD64
Ren'Py 8.3.2.24090902
Symulator Studenta 1.0
Wed Jan  8 18:39:54 2025
